Workbook

Sheet Read Me
A1: US Water Infrastructure — Analysis Workbook
A2: Historical spending · forward budget model · technical drivers · Core & Main and Ferguson
A4: What this workbook contains
A5: A quantitative companion to the written analysis. Nineteen tabs covering who funds US water infrastructure, what annual spend should look like through 2035, the engineering evidence for replacement, where the underlying asset data actually lives, the full downloaded time series, and how it all flows through to the two listed distributors with direct exposure.
A7: Tab | B7: What it holds | C7: Formula-driven?
A8: Dashboard | B8: Headline figures pulled from the other tabs | C8: Yes — all links
A9: Assumptions | B9: Every model input in one place. THIS IS THE TAB TO EDIT. | C9: Inputs (blue/yellow)
A10: Forward Model | B10: National water capital spending build-up, 2026–2035 | C10: Yes
A11: Scenarios | B11: Bear / base / bull, driven off the Assumptions levers | C11: Yes
A12: Historical Spending | B12: CBO 1956–2023 series, Census construction, local capital | C12: Partly
A13: Federal Programs | B13: SRF, IIJA, WIFIA, earmarks, WRDA 2026 | C13: Partly
A14: Needs Estimates | B14: The four published studies, annualised and reconciled | C14: Yes
A15: Pipe and Assets | B15: USU break rates, miles by material, asset inventory | C15: Yes
A16: Regulatory | B16: Lead & Copper Rule Improvements, PFAS, CSO consent decrees | C16: Partly
A17: Core and Main | B17: Five-year P&L, end-market mix, guidance, derived metrics | C17: Yes
A18: Ferguson | B18: Eight-year P&L, US customer groups, waterworks estimate | C18: Yes
... A25: Sources | B25: Every source with its known interest or bias | C25: No
A27: Colour legend
A28: Format | B28: Meaning | C28: Example
A29: Blue text | B29: Hardcoded input — safe to change | C29: 68.0
A30: Black text | B30: Formula — do not overwrite | C30: SUM(B2:B9)
A31: Green text | B31: Link to another tab in this workbook | C31: 'Assumptions'!B5
A32: Yellow fill | B32: Key assumption the reader should review | C32: growth rate
A34: Method and provenance
A35: Company financials, segment mix, guidance and management quotations: sourced from Quartr — primary earnings releases, investor presentations and call transcripts. Core & Main Q1 FY2026 (10 Jun 2026) and FY2025 results (24 Mar 2026); Ferguson Q2 CY2026 (10 Aug 2026) and CY2025 transition period (24 Feb 2026).
A37: Public spending and technical data: CBO, US Census Bureau, Congressional Research Service, EPA, EPA Office of Inspector General, GAO, USGS, ASCE, AWWA, Utah State University and Bluefield Research. Each figure is attributed on its own row.
A39: Derived figures are computed by formula from cited inputs, never typed as results. Where a number is an estimate rather than a reported figure it is labelled ESTIMATE on its row.
A41: Caveats that belong on the front page
A42: DATA ACCESS. This workbook was assembled in an environment whose network policy blocked direct retrieval from cbo.gov, epa.gov, census.gov, congress.gov, fred.stlouisfed.org and infrastructurereportcard.org. Public-sector figures were obtained via search results summarising those primary documents. Attributions are to the correct primary source, but VERIFY EACH HEADLINE NUMBER against the source document before relying on it for an investment decision. Company financials do not carry this caveat — they came from Quartr's primary filings.
A44: THE CAPITAL BASE. The $68bn 2026 base on the Assumptions tab is a reconciliation of four independent sources, not a single reported figure — see the Needs Estimates tab for the derivation. An earlier draft of this analysis used $88bn, which was Census construction put in place; that series bundles solid waste with sewerage and includes private work, and overstates water capital spending by roughly 30%.
A46: NO VALUATION. This workbook contains no valuation, no price target and no recommendation. It sizes a market, models its trajectory, and tests the engineering claims underneath it.
A48: Built August 2026.

Sheet Assumptions
A1: Assumptions
A2: Blue = editable input. Every model figure elsewhere in this workbook resolves back to this tab.
A4: Core model inputs
A5: Input | B5: Value | C5: Unit | D5: Basis
A6: National water capital spending, 2026 | B6: 68 | C6: $bn | D6: Reconciliation of four sources — see Needs Estimates tab. CBO water utilities capital $59bn (2023) escalated; Census adjusted for solid-waste content; ASCE and AWWA implied.
A7: Organic growth rate, nominal | B7: 0.045 | C7: % p.a. | D7: Bluefield treatment capex CAGR 4.4%; water and sewer rate growth ~5%.
A8: IIJA gross federal step-down | B8: 8.7 | C8: $bn p.a. | D8: Annual SRF funding fell from ~$2.7bn (FY2021) to ~$11.4bn (FY2022-26) — National League of Cities.
A9: Less: permanent revolving offset | B9: 2 | C9: $bn p.a. | D9: ESTIMATE. ~50/50 grant vs loan split implies ~$25bn permanent SRF corpus supporting ongoing lending.
A10: Net steady-state IIJA drag | B10: =B8-B9 -> 6.7 | C10: $bn p.a. | D10: Formula. The figure that actually leaves the system once revolving lending is netted off.
A11: as % of the 2026 capital base | B11: =B10/B6 -> 0.098529412 | C11: % | D11: Formula. The honest measure of the funding cliff.
A13: Scenario levers
A14: Scenario | B14: Organic growth | C14: IIJA drag ($bn) | D14: Regulatory adder multiplier
A15: Bear | B15: 0.03 | C15: 9 | D15: 0.5
A16: Base | B16: =B7 -> 0.045 | C16: =B10 -> 6.7 | D16: 1
A17: Bull | B17: 0.055 | C17: 4 | D17: 1.1
A18: Bear: FY2027 House 16% SRF cut sustained, no WRDA reauthorisation, rate growth decelerates to 3%, LCRI struck down in part. Bull: WRDA 2026 appropriated in full, LCRI upheld, rate growth holds 5.5%.
A21: Year-indexed drivers
A22: Driver | B22: Unit | C22: 2026 | D22: 2027 | E22: 2028 | F22: 2029 | G22: 2030 | H22: 2031 | I22: 2032 | J22: 2033 | K22: 2034 | L22: 2035
A23: IIJA drawdown phasing | B23: % of full effect | C23: 0 | D23: 0.15 | E23: 0.4 | F23: 0.75 | G23: 1 | H23: 1 | I23: 1 | J23: 1 | K23: 1 | L23: 1
A24: Lead service line adder | B24: $bn | C24: 0 | D24: 2 | E24: 3.5 | F24: 5 | G24: 5.5 | H24: 5.5 | I24: 5 | J24: 4.5 | K24: 3.5 | L24: 2
A25: PFAS adder | B25: $bn | C25: 0 | D25: 1 | E25: 1.8 | F25: 2.5 | G25: 2.5 | H25: 2 | I25: 1.5 | J25: 1.2 | K25: 1 | L25: 1
A27: Phasing: only about a third of the ~$50bn IIJA water money had reached municipalities by mid-2026 (Core & Main, Q1 FY2026 call), so the drawdown lands across 2027-2030 rather than at expiry.
A28: Lead adder: 9.2m lines at $4,700-$6,930 each (EPA) over the LCRI ten-year window, net of the $15bn of dedicated IIJA funding already inside the base.
A29: PFAS adder: incremental capital and O&M above base. EPA's 18 May 2026 proposal retains only PFOA and PFOS and would slip compliance to 2031, so spend shifts right and the peak is lower than the 2024 six-compound rule implied.

Sheet Forward Model
A1: Forward Model — National Water Capital Spending
A2: $bn nominal. Every cell is a formula off the Assumptions tab.
A4: Line | B4: Basis | C4: 2026 | D4: 2027 | E4: 2028 | F4: 2029 | G4: 2030 | H4: 2031 | I4: 2032 | J4: 2033 | K4: 2034 | L4: 2035
A5: Organic base | B5: grows at assumed rate | C5: =Assumptions!$B$6*(1+Assumptions!$B$7)^0 -> 68 | D5: =Assumptions!$B$6*(1+Assumptions!$B$7)^1 -> 71.06 | E5: =Assumptions!$B$6*(1+Assumptions!$B$7)^2 -> 74.2577 | F5: =Assumptions!$B$6*(1+Assumptions!$B$7)^3 -> 77.599296 | G5: =Assumptions!$B$6*(1+Assumptions!$B$7)^4 -> 81.091265 | H5: =Assumptions!$B$6*(1+Assumptions!$B$7)^5 -> 84.740372 | I5: =Assumptions!$B$6*(1+Assumptions!$B$7)^6 -> 88.553688 | J5: =Assumptions!$B$6*(1+Assumptions!$B$7)^7 -> 92.538604 | K5: =Assumptions!$B$6*(1+Assumptions!$B$7)^8 -> 96.702842 | L5: =Assumptions!$B$6*(1+Assumptions!$B$7)^9 -> 101.05447
A6: IIJA drawdown | B6: net drag x phasing | C6: =-Assumptions!$B$10*Assumptions!C$23 -> 0 | D6: =-Assumptions!$B$10*Assumptions!D$23 -> -1.005 | E6: =-Assumptions!$B$10*Assumptions!E$23 -> -2.68 | F6: =-Assumptions!$B$10*Assumptions!F$23 -> -5.025 | G6: =-Assumptions!$B$10*Assumptions!G$23 -> -6.7 | H6: =-Assumptions!$B$10*Assumptions!H$23 -> -6.7 | I6: =-Assumptions!$B$10*Assumptions!I$23 -> -6.7 | J6: =-Assumptions!$B$10*Assumptions!J$23 -> -6.7 | ... L6: =-Assumptions!$B$10*Assumptions!L$23 -> -6.7
A7: Lead service lines | B7: regulatory adder | C7: =Assumptions!C$24 -> 0 | D7: =Assumptions!D$24 -> 2 | E7: =Assumptions!E$24 -> 3.5 | F7: =Assumptions!F$24 -> 5 | G7: =Assumptions!G$24 -> 5.5 | H7: =Assumptions!H$24 -> 5.5 | I7: =Assumptions!I$24 -> 5 | J7: =Assumptions!J$24 -> 4.5 | ... L7: =Assumptions!L$24 -> 2
A8: PFAS | B8: regulatory adder | C8: =Assumptions!C$25 -> 0 | D8: =Assumptions!D$25 -> 1 | E8: =Assumptions!E$25 -> 1.8 | F8: =Assumptions!F$25 -> 2.5 | G8: =Assumptions!G$25 -> 2.5 | H8: =Assumptions!H$25 -> 2 | I8: =Assumptions!I$25 -> 1.5 | J8: =Assumptions!J$25 -> 1.2 | ... L8: =Assumptions!L$25 -> 1
A9: Total capital spending | B9: sum | C9: =SUM(C5:C8) -> 68 | D9: =SUM(D5:D8) -> 73.055 | E9: =SUM(E5:E8) -> 76.8777 | F9: =SUM(F5:F8) -> 80.074297 | G9: =SUM(G5:G8) -> 82.391265 | H9: =SUM(H5:H8) -> 85.540372 | I9: =SUM(I5:I8) -> 88.353688 | J9: =SUM(J5:J8) -> 91.538604 | ... L9: =SUM(L5:L8) -> 97.35447
A10: year on year | B10: growth | D10: =IF(C9=0,0,D9/C9-1) -> 0.074338235 | E10: =IF(D9=0,0,E9/D9-1) -> 0.052326329 | F10: =IF(E9=0,0,F9/E9-1) -> 0.041580283 | G10: =IF(F9=0,0,G9/F9-1) -> 0.028935232 | H10: =IF(G9=0,0,H9/G9-1) -> 0.038221369 | I10: =IF(H9=0,0,I9/H9-1) -> 0.03288876 | J10: =IF(I9=0,0,J9/I9-1) -> 0.036047346 | K10: =IF(J9=0,0,K9/J9-1) -> 0.032382373 | L10: =IF(K9=0,0,L9/K9-1) -> 0.030175049
A12: Summary
A13: Metric | B13: Value | D13: Note
A14: Cumulative spend 2027-2035 ($bn) | B14: =SUM(D9:L9) -> 769.68824 | D14: Base case. Sits between the escalated EPA survey floor and the ASCE/AWWA ceiling.
A15: CAGR 2026-2035 | B15: =(L9/C9)^(1/9)-1 -> 0.040677899 | D15: Mid-single-digit nominal. Not a boom, not a bust.
A16: Trough growth year | B16: =INDEX($C$4:$L$4,MATCH(MIN(D10:L10),D10:L10,0)+1) -> 2030 | D16: Where the federal drawdown concentrates.
A17: Trough growth rate | B17: =MIN(D10:L10) -> 0.028935232 | D17: Even at the worst point, growth stays positive.
A19: Reading: the federal drawdown costs roughly one to one and a half percentage points of market growth in the 2029-2030 window, and nothing thereafter. There is no credible scenario in which national water capital spending falls in nominal terms.

Sheet Scenarios
A1: Scenarios
A2: Bear / base / bull, each driven off its own row of levers on the Assumptions tab.
A4: Scenario | B4: Levers | C4: 2026 | D4: 2027 | E4: 2028 | F4: 2029 | G4: 2030 | H4: 2031 | I4: 2032 | J4: 2033 | K4: 2034 | L4: 2035
A5: Bear | B5: g / drag / adder | C5: =Assumptions!$B$6*(1+Assumptions!$B$15)^0-Assumptions!$C$15*Assumptions!C$23+Assumptions!$D$15*(Assumptions!C$24+Assumptions!C$25) -> 68 | D5: =Assumptions!$B$6*(1+Assumptions!$B$15)^1-Assumptions!$C$15*Assumptions!D$23+Assumptions!$D$15*(Assumptions!D$24+Assumptions!D$25) -> 70.19 | E5: =Assumptions!$B$6*(1+Assumptions!$B$15)^2-Assumptions!$C$15*Assumptions!E$23+Assumptions!$D$15*(Assumptions!E$24+Assumptions!E$25) -> 71.1912 | F5: =Assumptions!$B$6*(1+Assumptions!$B$15)^3-Assumptions!$C$15*Assumptions!F$23+Assumptions!$D$15*(Assumptions!F$24+Assumptions!F$25) -> 71.305436 | G5: =Assumptions!$B$6*(1+Assumptions!$B$15)^4-Assumptions!$C$15*Assumptions!G$23+Assumptions!$D$15*(Assumptions!G$24+Assumptions!G$25) -> 71.534599 | H5: =Assumptions!$B$6*(1+Assumptions!$B$15)^5-Assumptions!$C$15*Assumptions!H$23+Assumptions!$D$15*(Assumptions!H$24+Assumptions!H$25) -> 73.580637 | I5: =Assumptions!$B$6*(1+Assumptions!$B$15)^6-Assumptions!$C$15*Assumptions!I$23+Assumptions!$D$15*(Assumptions!I$24+Assumptions!I$25) -> 75.445556 | J5: =Assumptions!$B$6*(1+Assumptions!$B$15)^7-Assumptions!$C$15*Assumptions!J$23+Assumptions!$D$15*(Assumptions!J$24+Assumptions!J$25) -> 77.481423 | K5: =Assumptions!$B$6*(1+Assumptions!$B$15)^8-Assumptions!$C$15*Assumptions!K$23+Assumptions!$D$15*(Assumptions!K$24+Assumptions!K$25) -> 79.390366 | L5: =Assumptions!$B$6*(1+Assumptions!$B$15)^9-Assumptions!$C$15*Assumptions!L$23+Assumptions!$D$15*(Assumptions!L$24+Assumptions!L$25) -> 81.224577
A6: Base | B6: g / drag / adder | C6: =Assumptions!$B$6*(1+Assumptions!$B$16)^0-Assumptions!$C$16*Assumptions!C$23+Assumptions!$D$16*(Assumptions!C$24+Assumptions!C$25) -> 68 | D6: =Assumptions!$B$6*(1+Assumptions!$B$16)^1-Assumptions!$C$16*Assumptions!D$23+Assumptions!$D$16*(Assumptions!D$24+Assumptions!D$25) -> 73.055 | E6: =Assumptions!$B$6*(1+Assumptions!$B$16)^2-Assumptions!$C$16*Assumptions!E$23+Assumptions!$D$16*(Assumptions!E$24+Assumptions!E$25) -> 76.8777 | F6: =Assumptions!$B$6*(1+Assumptions!$B$16)^3-Assumptions!$C$16*Assumptions!F$23+Assumptions!$D$16*(Assumptions!F$24+Assumptions!F$25) -> 80.074297 | G6: =Assumptions!$B$6*(1+Assumptions!$B$16)^4-Assumptions!$C$16*Assumptions!G$23+Assumptions!$D$16*(Assumptions!G$24+Assumptions!G$25) -> 82.391265 | H6: =Assumptions!$B$6*(1+Assumptions!$B$16)^5-Assumptions!$C$16*Assumptions!H$23+Assumptions!$D$16*(Assumptions!H$24+Assumptions!H$25) -> 85.540372 | I6: =Assumptions!$B$6*(1+Assumptions!$B$16)^6-Assumptions!$C$16*Assumptions!I$23+Assumptions!$D$16*(Assumptions!I$24+Assumptions!I$25) -> 88.353688 | J6: =Assumptions!$B$6*(1+Assumptions!$B$16)^7-Assumptions!$C$16*Assumptions!J$23+Assumptions!$D$16*(Assumptions!J$24+Assumptions!J$25) -> 91.538604 | K6: =Assumptions!$B$6*(1+Assumptions!$B$16)^8-Assumptions!$C$16*Assumptions!K$23+Assumptions!$D$16*(Assumptions!K$24+Assumptions!K$25) -> 94.502842 | L6: =Assumptions!$B$6*(1+Assumptions!$B$16)^9-Assumptions!$C$16*Assumptions!L$23+Assumptions!$D$16*(Assumptions!L$24+Assumptions!L$25) -> 97.35447
A7: Bull | B7: g / drag / adder | C7: =Assumptions!$B$6*(1+Assumptions!$B$17)^0-Assumptions!$C$17*Assumptions!C$23+Assumptions!$D$17*(Assumptions!C$24+Assumptions!C$25) -> 68 | D7: =Assumptions!$B$6*(1+Assumptions!$B$17)^1-Assumptions!$C$17*Assumptions!D$23+Assumptions!$D$17*(Assumptions!D$24+Assumptions!D$25) -> 74.44 | E7: =Assumptions!$B$6*(1+Assumptions!$B$17)^2-Assumptions!$C$17*Assumptions!E$23+Assumptions!$D$17*(Assumptions!E$24+Assumptions!E$25) -> 79.9157 | F7: =Assumptions!$B$6*(1+Assumptions!$B$17)^3-Assumptions!$C$17*Assumptions!F$23+Assumptions!$D$17*(Assumptions!F$24+Assumptions!F$25) -> 85.098414 | G7: =Assumptions!$B$6*(1+Assumptions!$B$17)^4-Assumptions!$C$17*Assumptions!G$23+Assumptions!$D$17*(Assumptions!G$24+Assumptions!G$25) -> 89.040076 | H7: =Assumptions!$B$6*(1+Assumptions!$B$17)^5-Assumptions!$C$17*Assumptions!H$23+Assumptions!$D$17*(Assumptions!H$24+Assumptions!H$25) -> 93.12328 | I7: =Assumptions!$B$6*(1+Assumptions!$B$17)^6-Assumptions!$C$17*Assumptions!I$23+Assumptions!$D$17*(Assumptions!I$24+Assumptions!I$25) -> 96.911311 | J7: =Assumptions!$B$6*(1+Assumptions!$B$17)^7-Assumptions!$C$17*Assumptions!J$23+Assumptions!$D$17*(Assumptions!J$24+Assumptions!J$25) -> 101.18818 | K7: =Assumptions!$B$6*(1+Assumptions!$B$17)^8-Assumptions!$C$17*Assumptions!K$23+Assumptions!$D$17*(Assumptions!K$24+Assumptions!K$25) -> 105.30868 | L7: =Assumptions!$B$6*(1+Assumptions!$B$17)^9-Assumptions!$C$17*Assumptions!L$23+Assumptions!$D$17*(Assumptions!L$24+Assumptions!L$25) -> 109.39841
A9: Spread | B9: Basis | C9: 2026 | D9: 2027 | E9: 2028 | F9: 2029 | G9: 2030 | H9: 2031 | I9: 2032 | J9: 2033 | K9: 2034 | L9: 2035
A10: Bull less bear ($bn) | B10: range | C10: =C7-C5 -> 0 | D10: =D7-D5 -> 4.25 | E10: =E7-E5 -> 8.7245 | F10: =F7-F5 -> 13.792977 | G10: =G7-G5 -> 17.505477 | H10: =H7-H5 -> 19.542643 | I10: =I7-I5 -> 21.465755 | J10: =J7-J5 -> 23.70676 | ... L10: =L7-L5 -> 28.173834
A11: as % of bear | B11: range | C11: =C10/C5 -> 0 | D11: =D10/D5 -> 0.060549936 | E11: =E10/E5 -> 0.12255026 | F11: =F10/F5 -> 0.19343515 | G11: =G10/G5 -> 0.24471343 | H11: =H10/H5 -> 0.26559492 | I11: =I10/I5 -> 0.2845198 | J11: =J10/J5 -> 0.30596702 | ... L11: =L10/L5 -> 0.34686342
A13: Scenario endpoints
A14: Scenario | B14: 2030 ($bn) | C14: 2035 ($bn) | D14: CAGR 2026-35
A15: Bear | B15: =G5 -> 71.534599 | C15: =L5 -> 81.224577 | D15: =(L5/C5)^(1/9)-1 -> 0.019941807
A16: Base | B16: =G6 -> 82.391265 | C16: =L6 -> 97.35447 | D16: =(L6/C6)^(1/9)-1 -> 0.040677899
A17: Bull | B17: =G7 -> 89.040076 | C17: =L7 -> 109.39841 | D17: =(L7/C7)^(1/9)-1 -> 0.054252593
A19: The bear-to-bull spread by 2035 is the honest measure of confidence in this forecast. The direction, however, is up in every case — the disagreement is about pace, not sign.

Sheet Historical Spending
A1: Historical Spending
A2: Who actually pays for US water infrastructure.
A4: CBO — public spending on transportation and water infrastructure, 2023
A5: Metric | B5: Value | C5: Unit | D5: Share | E5: Source
A6: Total, all transportation and water infrastructure | B6: 626 | C6: $bn | E6: CBO, Public Spending on Transportation and Water Infrastructure 1956-2023, Feb 2025
A7: as % of GDP | B7: 0.023 | C7: % | E7: CBO
A8: Water utilities — total spending | B8: 175 | C8: $bn | D8: =B8/B6 -> 0.27955272 | E8: CBO via USAFacts. Water utilities take ~28% of the total.
A9: of which capital | B9: 59 | C9: $bn | D9: =B9/B8 -> 0.33714286 | E9: CBO. THIS IS THE ANCHOR FOR THE FORWARD MODEL BASE.
A10: of which operations and maintenance | B10: 114 | C10: $bn | D10: =B10/B8 -> 0.65142857 | E10: CBO. O&M is the majority — capital is the minority of utility spending.
A11: State and local share of water infrastructure | B11: 0.92 | C11: % | E11: CBO. Rises to ~96% on the narrower water supply and wastewater facilities definition.
A12: Federal share of water infrastructure | B12: 0.08 | C12: % | E12: CBO
A13: O&M as % of all public infrastructure spending | B13: 0.567 | C13: % | E13: CBO — $355bn of $625.8bn in 2023. Rising over time.
A14: State and local share of ALL public infrastructure | B14: 0.79 | C14: % | E14: CBO — $494.2bn of $625.8bn in 2023.
A16: Census Bureau — value of construction put in place (C30)
A17: Category | B17: Value | C17: Unit | D17: Basis | E17: Source and caveat
A18: Water supply — total construction | B18: 36.5 | C18: $bn | D18: SAAR Jan-2026 | E18: Census C30. Includes private work.
A19: Water supply — public construction | B19: 34.8 | C19: $bn | D19: SAAR Jan-2026 | E19: Census C30 / FRED PBWSCONS
A20: Sewage and waste disposal — total | B20: 54.3 | C20: $bn | D20: SAAR Jan-2026 | E20: Census C30. CAUTION: bundles SOLID WASTE facilities with sewerage — overstates wastewater.
A21: Sewage and waste disposal — public | B21: 53 | C21: $bn | D21: SAAR Jan-2026 | E21: Census C30
A22: Naive sum (both categories, total construction) | B22: =B18+B20 -> 90.8 | C22: $bn | D22: formula | E22: This is the $88bn figure an earlier draft used as the capital base. It is NOT water capital spending — see the reconciliation on the Needs Estimates tab.
A24: Longer-run local capital spending
A25: Metric | B25: Value | C25: Unit | D25: Period | E25: Source
A26: Local capital spending — sewer, cumulative | B26: 350 | C26: $bn | D26: 2012-2024 | E26: US Conference of Mayors, 2025 Public Infrastructure Spending
A27: annual average | B27: =B26/13 -> 26.923077 | C27: $bn | D27: formula | E27: Local government only
A28: Local capital spending — water supply, cumulative | B28: 226 | C28: $bn | D28: 2012-2024 | E28: US Conference of Mayors
A29: annual average | B29: =B28/13 -> 17.384615 | C29: $bn | D29: formula | E29: Local government only
A30: All public community-asset capital spending, 2012 | B30: 279 | C30: $bn | D30: 2012 | E30: US Conference of Mayors
A31: All public community-asset capital spending, 2024 | B31: 492 | C31: $bn | D31: 2024 | E31: US Conference of Mayors
A32: growth 2012-2024 | B32: =B31/B30-1 -> 0.76344086 | C32: % | D32: formula | E32: +76%
A34: The real funding engine — rates, debt and water loss
A35: Metric | B35: Value | C35: Unit | D35: Period | E35: Source
A36: Water and sewer bill increase | B36: 0.051 | C36: % | D36: 2025 | E36: Bluefield Research, US Municipal Water & Sewer Rate Index (50 cities)
A37: cumulative five-year increase | B37: 0.242 | C37: % | D37: 2020-2025 | E37: Bluefield Research
A38: water rates | B38: 0.06 | C38: % | D38: 2024-25 | E38: Bluefield Research
A39: wastewater rates | B39: 0.048 | C39: % | D39: 2024-25 | E39: Bluefield Research
A40: Water and sewer bond issuance | B40: 27.9 | C40: $bn | D40: 2010 low | E40: Historical reference range
A41: upper end of range | B41: 39.9 | C41: $bn | D41: 2013 high | E41: Historical reference range
A42: Non-revenue water — share of treated supply | B42: 0.195 | C42: % | D42: current | E42: Bluefield Research
A43: volume lost daily | B43: 6.75 | C43: bn gallons/day | D43: current | E43: Bluefield Research
A44: lost revenue | B44: 6.4 | C44: $bn p.a. | D44: current | E44: Bluefield Research
...

Sheet Federal Programs
A1: Federal Programs
A2: Four federal channels. Only one is large, and it expires 30 September 2026.
A4: State Revolving Funds — appropriations
A5: Item | B5: Value | C5: Unit | D5: Period | E5: Source
A6: Total annual SRF funding, pre-IIJA | B6: 2.7 | C6: $bn | D6: FY2021 | E6: National League of Cities
A7: Total annual SRF funding, with IIJA | B7: 11.4 | C7: $bn | D7: FY2022-26 avg | E7: National League of Cities — a ~4x step up
A8: Clean Water SRF — total available | B8: 1.64 | C8: $bn | D8: FY2021 | E8: CRS
A9: Clean Water SRF — regular appropriation | B9: 1.6 | C9: $bn | D9: FY2025 | E9: CRS
A10: Clean Water SRF — IIJA supplemental | B10: 2.6 | C10: $bn | D10: FY2025 | E10: CRS
A11: Drinking Water SRF — regular appropriation | B11: 1.1 | C11: $bn | D11: FY2025 | E11: CRS
A12: Drinking Water SRF — IIJA supplemental | B12: 2.6 | C12: $bn | D12: FY2025 | E12: CRS
A13: EPA water infrastructure programs — total | B13: 3.04 | C13: $bn | D13: FY2026 | E13: P.L. 119-74, same as FY2025 enacted (P.L. 119-4)
A14: Regular appropriations for EPA water infrastructure programs have been FLAT across FY2024, FY2025 and FY2026. All growth in the period came from the IIJA supplemental.
A17: IIJA / Bipartisan Infrastructure Law supplemental — expiring
A18: Pot | B18: Amount | C18: Unit | D18: Period | E18: Note
A19: Clean Water SRF general supplemental | B19: 11.7 | C19: $bn | D19: FY2022-26 | E19: Predominantly loans
A20: Drinking Water SRF general supplemental | B20: 11.7 | C20: $bn | D20: FY2022-26 | E20: Predominantly loans
A21: DWSRF — lead service line replacement | B21: 15 | C21: $bn | D21: FY2022-26 | E21: High principal-forgiveness requirement
A22: DWSRF — emerging contaminants (PFAS) | B22: 4 | C22: $bn | D22: FY2022-26 | E22: Grant-like for disadvantaged communities
A23: Other pots (CWSRF emerging contaminants etc.) | B23: 7.6 | C23: $bn | D23: FY2022-26 | E23: Balance to the >$50bn headline
A24: Total IIJA water supplemental | B24: =SUM(B19:B23) -> 50 | C24: $bn | D24: FY2022-26 | E24: EPA states 'over $50 billion'. Expires 30 September 2026.
A26: The cliff arithmetic
A27: Step | B27: Value | C27: Unit | E27: Reasoning
A28: 1. Gross federal step-down | B28: =Assumptions!B8 -> 8.7 | C28: $bn p.a. | E28: $11.4bn (FY22-26) less $2.7bn (FY21)
A29: as % of the 2026 capital base | B29: =B28/Assumptions!B6 -> 0.12794118 | C29: % | E29: Formula
A30: 2. Share not yet at municipality level | B30: 0.67 | C30: % | E30: Core & Main, Q1 FY2026 call: 'only about a third or less of it has hit the municipality level yet'
A31: dollars still to disburse | B31: =B30*B24 -> 33.5 | C31: $bn | E31: Spreads the drawdown across 2027-2030 rather than at expiry
A32: 3. Permanent revolving offset | B32: =Assumptions!B9 -> 2 | C32: $bn p.a. | E32: ESTIMATE. ~50/50 grant vs loan split; loans recycle into the state corpus
A33: 4. Net steady-state drag | B33: =Assumptions!B10 -> 6.7 | C33: $bn p.a. | E33: Formula
A34: as % of the 2026 capital base | B34: =Assumptions!B11 -> 0.098529412 | C34: % | E34: The honest measure of the cliff — not the 100% often assumed
A36: WIFIA, earmarks and reauthorisation
A37: Item | B37: Value | C37: Unit | D37: As at | E37: Note
A38: WIFIA — cumulative financing closed | B38: 23 | C38: $bn | D38: May 2026 | E38: 152 closed loans
A39: WIFIA — total project value supported | B39: 51 | C39: $bn | D39: May 2026 | E39: Leverage, not subsidy
A40: WIFIA — capacity still available | B40: 11 | C40: $bn | D40: 2026 | E40: EPA waiving fees for small communities
A41: WIFIA — FY2025 closings | B41: 1.2 | C41: $bn | D41: FY2025 | E41: 8 loans
A42: WIFIA — 2026 year-to-date closings | B42: 0.682 | C42: $bn | D42: early 2026 | E42: 3 loans
A43: FY2027 House bill — proposed SRF cut | B43: -0.16 | C43: % | D43: FY2027 | E43: Committee markup, June 2026
A44: FY2027 DWSRF proposed level | B44: 0.91 | C44: $bn | D44: FY2027 | E44: Down from $1.126bn in FY2026
A45: FY2027 earmarks — water projects | B45: 1 | C45: $bn | D45: FY2027 | E45: ~1,200 projects, carved OUT of SRF not added to it
...

Sheet Needs Estimates
A1: Needs Estimates and the Capital Base
A2: The four published studies disagree by 3x because they measure different things.
A4: Study | B4: Headline | C4: Unit | D4: Annualised ($bn) | E4: What it measures / whose interest
A5: EPA 7th DWINSA (Sep 2023) | B5: 625 | C5: $bn / 20yr | D5: =B5/20 -> 31.25 | E5: SRF-ELIGIBLE drinking water projects, self-reported by states. Jan-2021 dollars; $648.8bn in 2022 dollars per CRS. Allocation instrument — states self-report into their own funding formula.
A6: EPA CWNS 2022 (Apr 2024) | B6: 630.1 | C6: $bn / 20yr | D6: =B6/20 -> 31.505 | E6: SRF-ELIGIBLE clean water needs with documentation. +73% vs 2012, but first survey with 100% state participation — which mechanically inflates the increase.
A7: ASCE Bridging the Gap (2024) | B7: 99 | C7: $bn/yr gap | D7: =B7+Assumptions!B6 -> 167 | E7: Annualised column = gap + actual spend. Full economic need incl. resilience and growth, from the civil engineers' professional society. Up from $81bn in 2021. NOTE: ASCE separately reports wastewater+stormwater annual capital NEEDS of $99bn with a $69bn gap — the same headline number used two different ways. Route 3 of the base reconciliation uses the latter.
A8: AWWA Beyond the Replacement Era (Mar 2026) | B8: 2250 | C8: $bn / 25yr | D8: =B8/25 -> 90 | E8: Drinking water ONLY. Replacement + PFAS + lead + climate + cyber + O&M. Midpoint of $2.1-2.4tn (2025 dollars). Utility trade association; requires a 168% increase in annual capital investment.
A10: EPA surveys — combined and escalated
A11: Step | B11: Value | C11: Unit | E11: Basis
A12: Combined annualised eligible need | B12: =D5+D6 -> 62.755 | C12: $bn/yr | E12: 2021/2022 dollars, un-escalated
A13: Construction cost escalation | B13: 0.045 | C13: % p.a. | E13: Assumed
A14: Years to escalate | B14: 4.5 | C14: yrs | E14: Mid-2021/22 base to 2026
A15: Escalated eligible need, 2026 dollars | B15: =B12*(1+B13)^B14 -> 76.501798 | C15: $bn/yr | E15: Formula
A17: Reconciling the capital base — four independent routes to the same number
A18: Route | B18: Value | C18: Unit | E18: Derivation
A19: 1. CBO water utilities capital, 2023 | B19: 59 | C19: $bn | E19: CBO. Public sector, water supply and wastewater.
A20: escalated to 2026 at 4.5% p.a. | B20: =B19*(1+B13)^3 -> 67.328801 | C20: $bn | E20: Formula
A21: 2. Census water supply (total construction) | B21: 36.5 | C21: $bn | E21: Census C30, SAAR Jan-2026
A22: Census sewage and waste disposal | B22: 54.3 | C22: $bn | E22: Census C30, SAAR Jan-2026
A23: assumed sewerage share of that category | B23: 0.65 | C23: % | E23: ESTIMATE. The rest is solid waste disposal — landfill, waste-to-energy.
A24: adjusted total, public share (95%) | B24: =(B21+B22*B23)*0.95 -> 68.20525 | C24: $bn | E24: Formula
A25: 3. ASCE implied wastewater + stormwater actual | B25: 30 | C25: $bn | E25: ASCE: annual capital needs $99bn, gap $69bn, so ~30% of needs met.
A26: 4. AWWA implied drinking water actual | B26: =D8/2.68 -> 33.58209 | C26: $bn | E26: AWWA requires a 168% increase to reach its target, so current spend is target / 2.68.
A27: routes 3 + 4 combined | B27: =B25+B26 -> 63.58209 | C27: $bn | E27: Formula
A28: Average of routes 1 and 2 (primary) | B28: =AVERAGE(B20,B24) -> 67.767026 | C28: $bn | E28: The two strongest routes: a non-partisan scorekeeper and official construction statistics.
A29: Average of all three routes | B29: =AVERAGE(B20,B24,B27) -> 66.372047 | C29: $bn | E29: Routes 3 and 4 are weaker — both read advocacy claims backwards — and pull the average down.
A30: Implied range | B30: =MIN(B20,B24,B27) -> 63.58209 | C30: $bn | D30: =MAX(B20,B24,B27) -> 68.20525 | E30: Low to high across the three routes.
A31: ADOPTED BASE | B31: =Assumptions!B6 -> 68 | C31: $bn | E31: Rounded to $68bn — the midpoint of the two primary routes. Sits at the upper end of the three-route range because routes 3 and 4 are derived from advocacy studies read in reverse and are the least reliable. Change it on the Assumptions tab to test the low end.
A32: variance vs three-route average | B32: =Assumptions!B6/B29-1 -> 0.02452769 | C32: % | E32: Formula. The model is ~2.5% above the most conservative reading of the base.
A33: Gap: escalated need less actual spend | B33: =B15-Assumptions!B6 -> 8.5017977 | C33: $bn/yr | E33: The documented, SRF-eligible shortfall — an order of magnitude below the ASCE headline.
A34: as % of actual spend | B34: =B33/Assumptions!B6 -> 0.12502644 | C34: % | E34: Formula
A36: WHY THE FOUR STUDIES DIVERGE. The EPA surveys are floors by construction: they count only what states could document as eligible, and assume a 0.5%/yr pipe replacement rate — which imputes a 200-YEAR pipe life against an observed 53-year average failure age. The ASCE and AWWA figures are ceilings by construction, produced by parties that advocate for higher appropriations. The truth is bracketed, not split.
A38: Market-research forecasts (the view that maps to distributor revenue)
A39: Forecast | B39: Value | C39: Unit | D39: Period | E39: Source
A40: US municipal water + wastewater treatment capex | B40: 515.4 | C40: $bn | D40: through 2035 | E40: Bluefield Research — 4.4% CAGR
A41: starting annual rate | B41: 37.2 | C41: $bn | D41: 2026 | E41: Bluefield Research
A42: ending annual rate | B42: 57.3 | C42: $bn | D42: 2035 | E42: Bluefield Research
A43: of which wastewater | B43: 310.4 | C43: $bn | D43: through 2035 | E43: Bluefield Research — 58% of total
A44: of which upgrades / rehab of existing assets | B44: 406.4 | C44: $bn | D44: through 2035 | E44: Bluefield Research — 79%. The replacement thesis, quantified.
A45: US + Canada municipal pipe capex | B45: 99.3 | C45: $bn | D45: 2026-2035 | E45: Bluefield Research — ~$10bn/yr

Sheet Pipe and Assets
A1: Pipe and Assets — the Engineering Evidence
A2: Utah State University, Water Main Break Rates in the USA and Canada, Dec 2023.
A4: Study scope
A5: Metric | B5: Value | C5: Unit | F5: Note
A6: Utilities surveyed | B6: 802 | C6: count | F6: 49 US states and all 10 Canadian provinces
A7: Population served by respondents | B7: 0.3 | C7: % | F7: >30% of the US and Canada population
A8: Miles of main represented | B8: 400000 | C8: miles | F8: >17% of the estimated 2.3m miles in both countries
A9: Publication date | B9: 2023 | C9: year | F9: Released Feb 2024 by USU's Utah Water Research Laboratory
A10: BIAS NOTE: the study is academic but distributed by pipe-manufacturer interests, and its material-by-material results favour PVC. It is also the best dataset available — and its finding that break rates FELL cuts against its own $452bn funding-gap headline.
A13: Break rates and material mix
A14: Material | B14: Breaks per 100 mi/yr | C14: Miles surveyed | D14: % of surveyed miles | E14: % over 50 yrs old | F14: Failure mechanism
A15: Cast iron | B15: 28.6 | C15: 90657 | D15: =C15/$C$20 -> 0.24542021 | E15: 0.86 | F15: Graphitic corrosion — iron matrix leaches away leaving a graphite skeleton that holds shape and pressure until it fails without warning. Plus tuberculation.
A16: Asbestos cement | B16: 10.3 | C16: 42365 | D16: =C16/$C$20 -> 0.11468753 | E16: 0.41 | F16: Cement matrix leaches from both faces; progressive wall-strength loss. Handling, worker-safety and disposal premiums on replacement.
A17: Steel | B17: 9.2 | C17: 11358 | D17: =C17/$C$20 -> 0.030747574 | F17: External and internal corrosion; joint and weld failure.
A18: Ductile iron | B18: 5.1 | C18: 108670 | D18: =C18/$C$20 -> 0.29418373 | F18: Corrosion where unprotected; polyethylene encasement materially extends life.
A19: PVC | B19: 2.9 | C19: 116345 | D19: =C19/$C$20 -> 0.31496095 | F19: Low failure rate; failures typically installation-related or from impact/third-party damage.
A20: Total surveyed | C20: =SUM(C15:C19) -> 369395 | D20: =SUM(D15:D19) -> 1 | F20: Formula
A21: National average break rate | B21: 11.1 | F21: Down from 14.0 in the 2018 study — a ~20% decline in five years.
A22: 2018 study national average | B22: 14 | F22: USU 2018
A23: Change 2018 to 2023 | B23: =B21/B22-1 -> -0.20714286 | F23: THE COUNTER-EVIDENCE: the network is measurably getting MORE reliable, not less.
A24: Cast iron vs PVC failure ratio | B24: =B15/B19 -> 9.862069 | F24: The single most defensible number in the replacement case.
A26: Asset inventory and condition
A27: Metric | B27: Value | C27: Unit | F27: Source
A28: Drinking water transmission and distribution mains | B28: 2200000 | C28: miles | F28: EPA / ASCE
A29: Community water systems | B29: 50000 | C29: count | F29: EPA — of 148,000+ public water systems total
A30: Public sewers | B30: 800000 | C30: miles | F30: ASCE — plus ~500,000 miles of private laterals
A31: Publicly owned treatment works | B31: 17544 | C31: count | F31: EPA CWNS 2022 — serving 270.4m people, 82% of population
A32: POTW average utilisation of design capacity | B32: 0.81 | C32: % | F32: ASCE
A33: POTWs at or over design capacity | B33: 0.15 | C33: % | F33: ASCE
A34: Water mains over 50 years old | B34: 0.33 | C34: % | F34: USU 2023 — approximately 770,000 miles
A35: Water mains beyond useful life | B35: 0.194 | C35: % | F35: USU 2023 — approximately 452,000 miles
A36: Average age of failing water main | B36: 53 | C36: years | F36: USU 2023
A37: Estimated cost to replace aging mains | B37: 452 | C37: $bn | F37: USU 2023, US and Canada
A38: Water main breaks per year | B38: 260000 | C38: count | F38: USU 2023, US and Canada — one every two minutes
A39: Annual repair cost of those breaks | B39: 2.6 | C39: $bn | F39: USU 2023
... A41: Untreated CSO discharge | B41: 850 | C41: bn gallons/yr | F41: EPA
A42: Implied average cost per break | B42: =B39*1000000000/B38 -> 10000 | C42: $ | F42: Formula. Direct repair cost only — excludes boil-water notices, road closure and third-party damage.
A44: Demand — the evidence against capacity expansion
A45: Metric | B45: Value | C45: Unit | D45: Period | F45: Source
A46: Per capita withdrawal, 2000 | B46: 140 | C46: gal/capita/day | D46: 2000 | F46: USGS
...

Sheet Regulatory
A1: Regulatory Drivers
A2: Legally dated obligations — the highest-conviction component of the forecast.
A4: Lead and Copper Rule Improvements
A5: Item | B5: Value | C5: Unit | D5: Date / status | E5: Note
A6: National lead service lines | B6: 9200000 | C6: count | D6: EPA 7th DWINSA | E6: First-ever national count.
A7: EPA cost per line — low | B7: 4700 | C7: $ | D7: EPA | E7: Utilities dispute as too low.
A8: EPA cost per line — high | B8: 6930 | C8: $ | D8: EPA | E8: New York estimates up to $11,000.
A9: Implied national cost — low | B9: =B6*B7/1000000000 -> 43.24 | C9: $bn | D9: formula | E9: Consensus estimates cluster at $45-60bn.
A10: Implied national cost — high | B10: =B6*B8/1000000000 -> 63.756 | C10: $bn | D10: formula
A11: Dedicated IIJA funding | B11: 15 | C11: $bn | D11: FY2022-26 | E11: Covers roughly a quarter to a third.
A12: Unfunded balance (midpoint) | B12: =AVERAGE(B9:B10)-B11 -> 38.498 | C12: $bn | D12: formula | E12: Must come from rates. This is the rate-driver, not the grant story.
A13: Baseline inventory / plan deadline | D13: 1 November 2027 | E13: Inventory, replacement plan, school and childcare list, updated sampling plan.
A14: Full replacement deadline | D14: 2034-2037 | E14: Ten years from compliance date, REGARDLESS of measured lead levels.
A15: Litigation | D15: Oral argument expected Fall 2026 | E15: AWWA v. EPA — challenges mandated replacement of lines 'under the control' of the utility. THE LARGEST BINARY RISK IN THIS FORECAST.
A17: PFAS
A18: Item | B18: Value | C18: Unit | D18: Date / status | E18: Note
A19: PFOA / PFOS maximum contaminant level | B19: 4 | C19: ppt | D19: RETAINED | E19: EPA proposal of 18 May 2026 upholds these.
A20: Original compliance deadline | D20: 26 April 2029 | E20: 2024 final rule.
A21: Proposed extended deadline | D21: 26 April 2031 | E21: On request, not automatic — EPA declined an automatic extension.
A22: PFHxS, PFNA, GenX, Hazard Index MCLs | D22: PROPOSED FOR RESCISSION | E22: On legal and procedural grounds under the SDWA, NOT on the health science.
A23: Comment period | D23: Closed 20 July 2026 | E23: Public hearing held 7 July 2026.
A24: Sector treatment cost | B24: 50 | C24: $bn / 20yr | D24: AWWA / Black & Veatch | E24: Trade-association model produced to argue against a stricter rule.
A25: CERCLA disposal cost if designated | B25: 3.5 | C25: $bn p.a. | D25: potential | E25: Residuals disposal exposure.
A26: Household rate impact — low | B26: 305 | C26: $ p.a. | D26: AWWA
A27: Household rate impact — high | B27: 3570 | C27: $ p.a. | D27: AWWA | E27: Worst for small systems, where fewer households share the cost.
A28: NET EFFECT of the 2026 proposals: the PFAS opportunity is SMALLER and LATER than the 2024 rule implied. Retaining only PFOA and PFOS reduces the number of systems triggered, and slipping compliance two years pushes capital into 2029-2031. Any model built on the full six-compound rule is stale.
A31: Other regulatory drivers
A32: Driver | B32: Scale | C32: Unit | D32: Mechanism | E32: Note
A33: CSO / SSO consent decrees | B33: 860 | C33: communities | D33: Court-supervised Clean Water Act settlements | E33: A court order is not a budget line — non-deferrable, multi-decade.
A34: Untreated CSO discharge | B34: 850 | C34: bn gal/yr | D34: EPA | E34: Concentrated in older Northeast, Great Lakes and Pacific Northwest cities.
A35: POTW end-of-life | B35: 40 | C35: yr design life | D35: 1972 Clean Water Act cohort | E35: Equipment life 15-20 years; plants 40-50.
A36: Data centre water consumption today | B36: 18 | C36: bn gal/yr | D36: New demand | E36: Midpoint of 17-19bn.
A37: Data centre water consumption 2030 | B37: 85 | C37: bn gal/yr | D37: New demand | E37: Midpoint of 60-110bn. 97% supplied by municipal systems.

Sheet Core and Main
A1: Core & Main (CNM)
A2: Fiscal years end the Sunday nearest 31 January and are labelled by end date. $m unless stated. Data sourced from Quartr.
A4: Income statement — five years
A5: $m | B5: FY end Jan-2022 | C5: FY end Jan-2023 | D5: FY end Jan-2024 | E5: FY end Feb-2025 | F5: FY end Feb-2026 | G5: Note
A6: Net sales | B6: 5004 | C6: 6651 | D6: 6702 | E6: 7441 | F6: 7647 | G6: Quartr — standardised income statement
A7: growth | C7: =C6/B6-1 -> 0.32913669 | D7: =D6/C6-1 -> 0.0076680198 | E7: =E6/D6-1 -> 0.11026559 | F7: =F6/E6-1 -> 0.027684451 | G7: Formula
A8: Gross profit | B8: 1280 | C8: 1795 | D8: 1818 | E8: 1980 | F8: 2059 | G8: Quartr
A9: gross margin | B9: =B8/B6 -> 0.25579536 | C9: =C8/C6 -> 0.26988423 | D9: =D8/D6 -> 0.27126231 | E9: =E8/E6 -> 0.26609327 | F9: =F8/F6 -> 0.26925592 | G9: Formula
A10: EBITDA (standardised) | B10: 604 | C10: 918 | D10: 889 | E10: 905 | F10: 913 | G10: Quartr. Company-reported Adjusted EBITDA for FY end Feb-2026 was $931m.
A11: EBITDA margin | B11: =B10/B6 -> 0.12070344 | C11: =C10/C6 -> 0.13802436 | D11: =D10/D6 -> 0.13264697 | E11: =E10/E6 -> 0.12162344 | F11: =F10/F6 -> 0.11939323 | G11: Formula
A12: Operating income | B12: 425 | C12: 775 | D12: 740 | E12: 719 | F12: 722 | G12: Quartr
A13: Net income | B13: 225 | C13: 366 | D13: 371 | E13: 434 | F13: 462 | G13: Quartr
A14: Diluted EPS ($) | B14: 0.55 | C14: 2.13 | D14: 2.15 | E14: 2.13 | F14: 2.31 | G14: Quartr
A15: Revenue CAGR, FY22 to FY26 | B15: =(F6/B6)^(1/4)-1 -> 0.11184295 | G15: Formula. Includes the 2021-22 inflation surge.
A17: End-market and product mix — fiscal year ended 1 February 2026
A18: Segment | B18: % of net sales | C18: Implied $m | G18: Source
A19: Municipal | B19: 0.44 | C19: =B19*$F$6 -> 3364.68 | G19: Core & Main Q1 FY2026 investor presentation, slide 12
A20: Non-residential | B20: 0.38 | C20: =B20*$F$6 -> 2905.86 | G20: Core & Main Q1 FY2026 investor presentation, slide 12
A21: Residential | B21: 0.18 | C21: =B21*$F$6 -> 1376.46 | G21: Core & Main Q1 FY2026 investor presentation, slide 12
A22: Total | B22: =SUM(B19:B21) -> 1 | C22: =SUM(C19:C21) -> 7647 | G22: Formula
A24: Split | B24: Share | G24: Source
A25: New construction | B25: 0.5 | G25: Core & Main Q1 FY2026 deck
A26: Repair and replace | B26: 0.5 | G26: The least cyclical revenue in the sector — funded from rates and O&M
A28: Market position and scale
A29: Metric | B29: Value | C29: Unit | G29: Source
A30: US total addressable market | B30: 39 | C30: $bn | G30: Core & Main deck, based on third-party research
A31: US market share | B31: 0.2 | C31: % | G31: Core & Main deck
A32: US + Canada TAM | B32: 44 | C32: $bn | G32: Core & Main deck
A33: US + Canada market share | B33: 0.17 | C33: % | G33: Core & Main deck
A34: Branches | B34: 370 | C34: count | G34: As at 3 May 2026
A35: Associates | B35: 5600 | C35: count | G35: As at 3 May 2026
A36: Customers | B36: 60000 | C36: count | G36: As at 3 May 2026
A37: Products | B37: 225000 | C37: count | G37: As at 3 May 2026
A38: Cross-check: TAM x share | B38: =B30*B31*1000 -> 7800 | C38: $m | G38: Formula. Compare with reported net sales of $7,647m — internally consistent.
A40: Q1 fiscal 2026 (quarter ended 3 May 2026) and guidance
A41: Metric | B41: Q1 FY26 | C41: Q1 FY25 | D41: Change | G41: Note
A42: Net sales ($m) | B42: 1911 | C42: 1910 | D42: =B42/C42-1 -> 0.00052356021 | G42: Core & Main Q1 FY2026 deck
A43: Gross profit ($m) | B43: 520 | C43: 510 | D43: =B43/C43-1 -> 0.019607843 | G43: Core & Main Q1 FY2026 deck
A44: Adjusted EBITDA ($m) | B44: 226 | C44: 224 | D44: =B44/C44-1 -> 0.0089285714 | G44: Core & Main Q1 FY2026 deck
A45: Net income ($m) | B45: 113 | C45: 105 | D45: =B45/C45-1 -> 0.076190476 | G45: Core & Main Q1 FY2026 deck
...

Sheet Ferguson
A1: Ferguson Enterprises (FERG)
A2: Fiscal years ended 31 July through FY2025; the company then moved to a 31 December year end. $m. Data sourced from Quartr.
A4: Income statement — eight periods
A5: $m | B5: FY Jul-19 | C5: FY Jul-20 | D5: FY Jul-21 | E5: FY Jul-22 | F5: FY Jul-23 | G5: FY Jul-24 | H5: FY Jul-25 | I5: CY Dec-25 | J5: Note
A6: Net sales | B6: 22010 | C6: 21819 | D6: 22792 | E6: 28566 | F6: 29734 | G6: 29635 | H6: 30762 | I6: 31316 | J6: CY Dec-25 is a transition period, not comparable to the July years
A7: growth | C7: =C6/B6-1 -> -0.0086778737 | D7: =D6/C6-1 -> 0.044594161 | E7: =E6/D6-1 -> 0.2533345 | F7: =F6/E6-1 -> 0.040887769 | G7: =G6/F6-1 -> -0.0033295218 | H7: =H6/G6-1 -> 0.038029357 | I7: =I6/H6-1 -> 0.018009232 | J7: Formula
A8: Gross profit | B8: 6458 | C8: 6421 | D8: 6980 | E8: 8756 | F8: 9025 | G8: 9053 | H8: 9435 | I8: 9708 | J8: Quartr
A9: gross margin | B9: =B8/B6 -> 0.29341209 | C9: =C8/C6 -> 0.2942848 | D9: =D8/D6 -> 0.30624781 | E9: =E8/E6 -> 0.30651824 | F9: =F8/F6 -> 0.30352458 | G9: =G8/G6 -> 0.30548338 | H9: =H8/H6 -> 0.30670958 | I9: =I8/I6 -> 0.31000128 | J9: Formula
A10: EBITDA | C10: 1581 | D10: 2168 | E10: 3121 | F10: 2980 | G10: 2987 | H10: 2979 | I10: 3243 | J10: Quartr; FY Jul-19 not available
A11: Operating income | B11: 1402 | C11: 1422 | D11: 2034 | E11: 2820 | F11: 2659 | G11: 2652 | H11: 2606 | I11: 2789 | J11: Quartr
A12: operating margin | B12: =B11/B6 -> 0.063698319 | C12: =C11/C6 -> 0.065172556 | D12: =D11/D6 -> 0.089241839 | E12: =E11/E6 -> 0.098718757 | F12: =F11/F6 -> 0.089426246 | G12: =G11/G6 -> 0.08948878 | H12: =H11/H6 -> 0.084714908 | I12: =I11/I6 -> 0.089059905 | J12: Formula
A13: Net income | B13: 1108 | C13: 961 | D13: 1508 | E13: 2122 | F13: 1889 | G13: 1735 | H13: 1856 | I13: 2006 | J13: Quartr
A15: US net sales by customer group — quarter ended 30 June 2026
A16: Customer group | B16: % of US sales | C16: Growth Q2 CY26 | D16: Growth Q2 CY25 | E16: Implied $m/qtr | J16: Source
A17: Waterworks | B17: 0.24 | C17: 0.03 | D17: 0.15 | E17: =B17*$E$25 -> 2002.32 | J17: Ferguson Q2 CY2026 deck, slide 7
A18: Ferguson Home | B18: 0.2 | C18: -0.01 | D18: 0.02 | E18: =B18*$E$25 -> 1668.6 | J18: Ferguson Q2 CY2026 deck, slide 7
A19: Commercial / Mechanical | B19: 0.16 | C19: 0.15 | D19: 0.2 | E19: =B19*$E$25 -> 1334.88 | J19: Ferguson Q2 CY2026 deck, slide 7
A20: Residential Trade Plumbing | B20: 0.14 | C20: 0 | D20: -0.02 | E20: =B20*$E$25 -> 1168.02 | J20: Ferguson Q2 CY2026 deck, slide 7
A21: HVAC | B21: 0.13 | C21: 0.11 | D21: 0.01 | E21: =B21*$E$25 -> 1084.59 | J21: Ferguson Q2 CY2026 deck, slide 7
A22: Industrial | B22: 0.07 | C22: 0.18 | D22: 0.06 | E22: =B22*$E$25 -> 584.01 | J22: Ferguson Q2 CY2026 deck, slide 7
A23: Facilities Supply | B23: 0.04 | C23: 0.05 | D23: 0.02 | E23: =B23*$E$25 -> 333.72 | J23: Ferguson Q2 CY2026 deck, slide 7
A24: Fire & Fabrication | B24: 0.02 | C24: -0.13 | D24: 0.05 | E24: =B24*$E$25 -> 166.86 | J24: Ferguson Q2 CY2026 deck, slide 7
A25: US total | B25: =SUM(B17:B24) -> 1 | C25: 0.05 | D25: 0.068 | E25: 8343 | J25: US segment net sales, quarter ended 30 June 2026
A26: Canada | C26: -0.019 | E26: 408 | J26: Canada segment, same quarter
A27: Group total | C27: 0.046 | E27: 8751 | J27: Quarter ended 30 June 2026
A29: Waterworks revenue — ESTIMATE, not a reported figure
A30: Step | B30: Value | C30: Unit | J30: Basis
A31: Group revenue, calendar 2025 | B31: 31316 | C31: $m | J31: Reported
A32: Canada, annualised from Q2 | B32: =E26*4 -> 1632 | C32: $m | J32: ESTIMATE — $408m x 4
A33: Implied US revenue | B33: =B31-B32 -> 29684 | C33: $m | J33: Formula
A34: Waterworks share — full-year low | B34: 0.22 | C34: % | J34: ESTIMATE. Q2 is seasonally the strongest waterworks quarter, so the reported 24% overstates the full-year share.
A35: Waterworks share — Q2 reported | B35: 0.24 | C35: % | J35: Reported
A36: Estimated waterworks revenue — low | B36: =B33*B34 -> 6530.48 | C36: $m | J36: Formula
A37: Estimated waterworks revenue — high | B37: =B33*B35 -> 7124.16 | C37: $m | J37: Formula
A38: as % of group revenue | B38: =B37/B31 -> 0.22749266 | C38: % | J38: Formula
A40: Other
A41: Item | B41: Value | C41: Unit | J41: Note
A42: Large capital projects, % of group revenue | B42: 0.07 | C42: % | J42: Mid- to high-single-digit and trending up. Backlogs building above realised growth rates, incl. waterworks.
A43: Commodities, % of revenue | B43: 0.15 | C43: % | J43: PVC still in double-digit deflation in Q2 CY26.
A44: FloWorks acquisition — price | B44: 1600 | C44: $m | J44: ~$1bn revenue; ~10x LTM adjusted EBITDA incl. synergies; expected close Q3 2026.
...

Sheet Comparison
A1: Core & Main vs Ferguson
A2: Two very different ways to own the same theme. Sensitivity computed by formula.
A4: Side by side
A5: Metric | B5: Core & Main | C5: Ferguson | D5: Note
A6: Latest full-year revenue ($m) | B6: ='Core and Main'!F6 -> 7647 | C6: =Ferguson!I6 -> 31316 | D6: CNM: FY ended 1 Feb 2026. FERG: calendar 2025.
A7: Estimated waterworks revenue ($m) | B7: ='Core and Main'!F6 -> 7647 | C7: =Ferguson!B37 -> 7124.16 | D7: CNM is 100% water. FERG figure is an ESTIMATE — see Ferguson tab.
A8: as % of group revenue | B8: =B7/B6 -> 1 | C8: =C7/C6 -> 0.22749266 | D8: Formula
A9: Municipal revenue ($m) | B9: ='Core and Main'!C19 -> 3364.68 | C9: n/d | D9: Ferguson does not disclose a municipal split.
A10: as % of group revenue | B10: =B9/B6 -> 0.44 | C10: n/d | D10: Formula
A11: Profitability margin | B11: 0.122 | C11: 0.107 | D11: CNM adjusted EBITDA margin FY2025. FERG adjusted operating margin Q2 CY26 — not like for like.
A12: Repair & replace share | B12: 0.5 | C12: n/d | D12: CNM deck. Ferguson does not disclose.
A14: Combined market position
A15: Metric | B15: Value | D15: Basis
A16: Combined waterworks revenue ($m) | B16: =B7+C7 -> 14771.16 | D16: Formula
A17: US TAM ($m) | B17: ='Core and Main'!B30*1000 -> 39000 | D17: Core & Main deck
A18: Combined share of US TAM | B18: =B16/B17 -> 0.37874769 | D18: A duopoly at the head of a long fragmented tail — the structural reason both can consolidate and hold pricing.
A20: Sensitivity — what 100bp of market growth is actually worth
A21: Metric | B21: Core & Main | C21: Ferguson | D21: Note
A22: Exposed revenue base ($m) | B22: =B9 -> 3364.68 | C22: =C7 -> 7124.16 | D22: CNM: municipal revenue. FERG: estimated waterworks revenue.
A23: Market growth change | B23: 0.01 | C23: 0.01 | D23: Editable — change to test other increments.
A24: Revenue impact ($m) | B24: =B22*B23 -> 33.6468 | C24: =C22*C23 -> 71.2416 | D24: Formula
A25: as % of group revenue | B25: =B24/B6 -> 0.0044 | C25: =C24/C6 -> 0.0022749266 | D25: THE NUMBER MOST INVESTORS GET WRONG. Even for the pure play this is under half a percent.
A26: EBITDA impact ($m) | B26: =B24*B11 -> 4.1049096 | C26: =C24*C11 -> 7.6228512 | D26: At current margins. Incremental margin on distribution volume is typically higher.
A28: IIJA peak drag scenario | B28: Core & Main | C28: Ferguson | D28: Note
A29: Market growth points lost at peak | B29: 0.0125 | C29: 0.0125 | D29: Midpoint of the 1.0-1.5pt range, concentrated in 2029-2030 — see Forward Model.
A30: Revenue growth impact | B30: =B22*B29/B6 -> 0.0055 | C30: =C22*C29/C6 -> 0.0028436582 | D30: Formula. Well under 100bps for either company.
A32: Residential construction — 18% of Core & Main's mix and about half of Ferguson's US mix — moves both companies materially more than the federal funding question does. That is the risk worth underwriting.

Sheet Dashboard
A1: Dashboard
A2: Every figure below is a live link to the tab that derives it.
A4: The funding map
A5: Metric | B5: Value | C5: Unit | D5: Reads
A6: State and local share of water infrastructure | B6: ='Historical Spending'!B10 -> 114 | C6: % | D6: CBO. Federal policy sets rules far more powerfully than it sets budgets.
A7: Water utilities total spending, 2023 | B7: ='Historical Spending'!B7 -> 0.023 | C7: $bn | D7: CBO — of which capital is the minority.
A8: of which capital | B8: ='Historical Spending'!B8 -> 175 | C8: $bn | D8: The anchor for the forward model.
A9: Water and sewer bill increase, 2025 | B9: ='Historical Spending'!B44 -> 6.4 | C9: % | D9: Bluefield. The variable that matters most for distributor revenue.
A11: The forward model
A12: Metric | B12: Value | C12: Unit | D12: Reads
A13: 2026 capital base | B13: =Assumptions!B6 -> 68 | C13: $bn | D13: Reconciliation of four independent sources.
A14: 2030 total spending (base case) | B14: ='Forward Model'!G9 -> 82.391265 | C14: $bn
A15: 2035 total spending (base case) | B15: ='Forward Model'!L9 -> 97.35447 | C15: $bn
A16: CAGR 2026-2035 | B16: =('Forward Model'!L9/'Forward Model'!C9)^(1/9)-1 -> 0.040677899 | C16: % | D16: Mid-single-digit nominal. Not a boom and not a bust.
A17: Net IIJA drag as % of base | B17: =Assumptions!B11 -> 0.098529412 | C17: % | D17: The honest measure of the cliff — not the 100% often assumed.
A18: 2035 bear case | B18: =Scenarios!L5 -> 81.224577 | C18: $bn
A19: 2035 bull case | B19: =Scenarios!L7 -> 109.39841 | C19: $bn | D19: No credible scenario has spending falling in nominal terms.
A21: The engineering evidence
A22: Metric | B22: Value | C22: Unit | D22: Reads
A23: Cast iron vs PVC failure ratio | B23: ='Pipe and Assets'!B24 -> 9.862069 | C23: x | D23: The single most defensible number in the replacement case.
A24: Change in national break rate, 2018-2023 | B24: ='Pipe and Assets'!B23 -> -0.20714286 | C24: % | D24: THE COUNTER-EVIDENCE. The network is getting more reliable, not less.
A25: Lead service lines | B25: =Regulatory!B5 -> Value | C25: count | D25: Hard legal replacement mandate.
A26: Lead replacement unfunded balance | B26: =Regulatory!B11 -> 15 | C26: $bn | D26: Must come from rates. This is the rate-driver.
A28: The companies
A29: Metric | B29: Value | C29: Unit | D29: Reads
A30: Core & Main revenue ($m) | B30: =Comparison!B6 -> 7647 | C30: $m | D30: FY ended 1 Feb 2026.
A31: Ferguson revenue ($m) | B31: =Comparison!C6 -> 31316 | C31: $m | D31: Calendar 2025.
A32: Combined share of US TAM | B32: =Comparison!B18 -> 0.37874769 | C32: % | D32: A duopoly at the head of a fragmented tail.
A33: 100bp market growth — CNM revenue impact | B33: =Comparison!B25 -> 0.0044 | C33: % of sales | D33: The IIJA cliff is worth less than this to either company.
A34: 100bp market growth — FERG revenue impact | B34: =Comparison!C25 -> 0.0022749266 | C34: % of sales
A36: VERIFY BEFORE USE: public-sector figures in this workbook were obtained via search results summarising primary documents, because this environment's network policy blocked direct access to cbo.gov, epa.gov, census.gov, congress.gov and fred.stlouisfed.org. Company financials came from Quartr's primary filings and do not carry this caveat. See the Read Me tab.

Sheet Asset Data Sources
A1: Pipe Age and Repair History — What Is Public
A2: Where segment-level installation year and repair history can actually be obtained.
A4: The structural gap
A5: Sector | B5: National age registry? | C5: Granularity | D5: Publisher | E5: Note
A6: Natural gas + hazardous liquid | B6: YES | C6: National, by decade | D6: PHMSA | E6: By-Decade Inventory: mileage by decade of installation for gas distribution, gas transmission and hazardous liquid. Operators must file annual reports covering age, length, diameter, material.
A7: Water and wastewater | B7: NO | C7: None | D7: — | E7: No federal reporting requirement for pipe age. SDWIS carries compliance and violations but no distribution-system asset inventory. Responsibility sits with ~50,000 community water systems.
A8: CONSEQUENCE: every national water pipe-age figure in this workbook is a survey estimate, not a census. The USU study covers ~400,000 miles — over 17% of the 2.3m miles in the US and Canada.
A11: Tier 1 — asset-level and genuinely public
A12: Source type | B12: What it contains | C12: Granularity | D12: Cost | E12: Examples and caveats
A13: Municipal GIS open-data portals | B13: Water main layer: installation year, material, diameter, length, sometimes lining status | C13: Pipe segment | D13: Free | E13: Seattle Public Utilities Water Mains (incl. a 'Presumed Unlined' condition layer); Open Data DC; federated search via catalog.data.gov. THE BEST SOURCE FOR PIPE AGE. Install year often null on the oldest segments — precisely the ones that matter.
A14: Water main break datasets | B14: Break location and date | C14: Point location | D14: Free | E14: DC Water publishes five years of breaks, updated weekly. Records FAILURES, not planned replacement — a segment replaced on schedule generates no record.
A15: Street opening / excavation permits | B15: Who dug, where, when, why | C15: Street segment | D15: Free | E15: NYCStreets permit management; Chicago CDOT Office of Underground Coordination. The best available proxy for LAST PERIOD OF REPAIR, and it captures planned work that break data misses.
A16: Lead service line inventories | B16: Service line material by location incl. lead, galvanized-requiring-replacement and unknown | C16: Address / parcel | D16: Free | E16: Mandatory public accessibility since 16 Oct 2024; systems >50,000 must publish online. Baseline inventory and replacement plan due 1 Nov 2027, updated ANNUALLY. State dashboards: New York, Minnesota.
A18: Tier 2 — system-level, and the most useful for an investor
A19: Source type | B19: What it contains | C19: Granularity | D19: Cost | E19: Examples and caveats
A20: Municipal bond official statements | B20: System description: miles of main, material mix, age profile, capital plan, replacement rates, rate history | C20: Utility | D20: Free | E20: MSRB EMMA — official statements for essentially every muni bond since 1990, plus continuing disclosure. Disclosure liability compels the issuer to describe the asset. HIGHEST-DENSITY PUBLIC SOURCE.
A21: Asset management plans / CIPs | B21: Segment register with material, diameter, install year, replacement value, maintenance history; sequenced CIP | C21: Utility | D21: Free | E21: Published directly by some utilities, e.g. Sacramento Suburban Water District's Distribution Main Asset Management Plan. Availability is patchy.
A22: Investor-owned utility 10-Ks | B22: Replacement cycle, miles to be replaced, capital plans | C22: Company | D22: Free | E22: American Water: renewal rate improved from a 250-year cycle (2009) to ~125-year by 2028; ~2,000 miles 2024-2028; $34-38bn over ten years. An SEC filing, not an advocacy report.
A23: State PUC rate-case dockets | B23: Depreciation studies with assumed service lives by asset class; plant-in-service vintage | C23: Company / asset class | D23: Free | E23: Public docket filings, state by state.
A24: CSO / SSO consent decrees | B24: System condition assessments and dated remediation schedules | C24: System | D24: Free | E24: DOJ/EPA lodged decrees. Effectively a court-supervised published asset plan.
A26: Tier 3 — national aggregates (estimates, not censuses)
A27: Source | B27: What it gives | C27: Coverage | E27: Limitation
A28: USU Water Main Break Rates (Dec 2023) | B28: Break rate and age by material; avg failure age 53 yrs; 33% of mains >50 yrs | C28: 802 utilities, ~400,000 miles | E28: >17% of the 2.3m miles in US+Canada. Best available, still a sample.
A29: EPA CWNS 2022 | B29: FACILITY-LEVEL project and needs data, downloadable CSV or Access | C29: All states, 100% participation | E29: Projects and costs, NOT pipe age. Wastewater only.
A30: EPA 7th DWINSA | B30: National and state needs; 9.2m lead service lines | C30: National | E30: Aggregated. Underlying utility responses are not public.
A31: UMich Center for Sustainable Systems | B31: Average age of US water pipes 45 years (2020), up from 25 (1970) | C31: National | E31: Derived estimate, not a measurement.
A33: What does not exist
A34: Item | B34: Status | E34: Note
A35: Federal water analogue to PHMSA By-Decade Inventory | B35: DOES NOT EXIST | E35: No agency collects water pipe age.
A36: SDWIS distribution-system asset inventory | B36: DOES NOT EXIST | E36: SDWIS covers compliance, violations, enforcement and basic system inventory only.
A37: PIPEiD (Virginia Tech SWIM Center) | B37: EXISTS BUT NOT OPEN | E37: Bureau of Reclamation funded; data from 500+ US water utilities and 100 federal facilities. A SECURED utility decision-support platform, not an open dataset. Its existence is the clearest evidence the gap is real and recognised.
A38: AWIA s.2013 risk and resilience assessments | B38: CONFIDENTIAL BY STATUTE | E38: Deliberately withheld on security grounds.
A40: Recipe for a bottom-up demand estimate
A41: Step | B41: Action | E41: Output
A42: 1 | B42: Select the 20-30 utilities with the largest capital programmes | E42: Identifiable from EMMA issuance volume and CWNS project data
A43: 2 | B43: Pull each water main GIS layer; build a vintage histogram | E43: Miles by installation decade and material; implied replacement rate from year-on-year layer changes
A44: 3 | B44: Pull the EMMA official statement and CIP | E44: Stated forward capital plan; continuing disclosure gives actuals vs plan
A45: 4 | B45: Pull the LSL inventory, and from Nov 2027 the annual replacement plan | E45: Service line counts and realised replacement pace
A46: 5 | B46: Pull break datasets and street-opening permits | E46: Validation that stated replacement is physically happening
